Workbook
Name UPDATE: 'Data Sheet'!$E$1

Sheet Profit & Loss
A1: ='Data Sheet'!B1 -> AXIS BANK LTD | H1: =UPDATE | M1: SCREENER.IN
A3: Narration | B3: ='Data Sheet'!B16 -> 42825 | C3: ='Data Sheet'!C16 -> 43190 | D3: ='Data Sheet'!D16 -> 43555 | E3: ='Data Sheet'!E16 -> 43921 | F3: ='Data Sheet'!F16 -> 44286 | G3: ='Data Sheet'!G16 -> 44651 | H3: ='Data Sheet'!H16 -> 45016 | I3: ='Data Sheet'!I16 -> 45382 | ... K3: ='Data Sheet'!K16 -> 46112 | L3: Trailing | M3: Best Case | N3: Worst Case
A4: Sales
A5: Expenses
A6: Operating Profit
A7: Other Income
A8: Depreciation
A9: Interest
A10: Profit before tax
A11: Tax
A12: Net profit
A13: EPS
A14: Price to earning
A15: Price
... A19: OPM
G22: TRENDS: | H22: 10 YEARS | I22: 7 YEARS | J22: 5 YEARS | K22: 3 YEARS | L22: RECENT | M22: BEST | N22: WORST
H23: =IF(B4=0,"",POWER($K4/B4,1/9)-1) | I23: =IF(D4=0,"",POWER($K4/D4,1/7)-1) | J23: =IF(F4=0,"",POWER($K4/F4,1/5)-1) | K23: =IF(H4=0,"",POWER($K4/H4, 1/3)-1) | L23: =IF(ISERROR(MAX(IF(J4=0,"",(K4-J4)/J4),IF(K4=0,"",(L4-K4)/K4))),"",MAX(IF(J4=0,"",(K4-J4)/J4),IF(K4=0,"",(L4-K4)/K4)))
H24: =IF(SUM(B4:$K$4)=0,"",SUMPRODUCT(B19:$K$19,B4:$K$4)/SUM(B4:$K$4)) | I24: =IF(SUM(E4:$K$4)=0,"",SUMPRODUCT(E19:$K$19,E4:$K$4)/SUM(E4:$K$4)) | J24: =IF(SUM(G4:$K$4)=0,"",SUMPRODUCT(G19:$K$19,G4:$K$4)/SUM(G4:$K$4)) | K24: =IF(SUM(I4:$K$4)=0, "", SUMPRODUCT(I19:$K$19,I4:$K$4)/SUM(I4:$K$4))
H25: =IF(ISERROR(AVERAGEIF(B14:$L14,">0")),"",AVERAGEIF(B14:$L14,">0")) | I25: =IF(ISERROR(AVERAGEIF(E14:$L14,">0")),"",AVERAGEIF(E14:$L14,">0")) | J25: =IF(ISERROR(AVERAGEIF(G14:$L14,">0")),"",AVERAGEIF(G14:$L14,">0")) | K25: =IF(ISERROR(AVERAGEIF(I14:$L14,">0")),"",AVERAGEIF(I14:$L14,">0"))

Sheet Quarters
A1: ='Profit & Loss'!A1 -> AXIS BANK LTD | E1: =UPDATE | J1: SCREENER.IN
A3: Narration | B3: ='Data Sheet'!B41 -> 45382 | C3: ='Data Sheet'!C41 -> 45473 | D3: ='Data Sheet'!D41 -> 45565 | E3: ='Data Sheet'!E41 -> 45657 | F3: ='Data Sheet'!F41 -> 45747 | G3: ='Data Sheet'!G41 -> 45838 | H3: ='Data Sheet'!H41 -> 45930 | I3: ='Data Sheet'!I41 -> 46022 | ... K3: ='Data Sheet'!K41 -> 46203
A4: Sales | B4: ='Data Sheet'!B42 -> 0 | C4: ='Data Sheet'!C42 -> 0 | D4: ='Data Sheet'!D42 -> 0 | E4: ='Data Sheet'!E42 -> 0 | F4: ='Data Sheet'!F42 -> 0 | G4: ='Data Sheet'!G42 -> 0 | H4: ='Data Sheet'!H42 -> 0 | I4: ='Data Sheet'!I42 -> 0 | ... K4: ='Data Sheet'!K42 -> 0
A5: Expenses | B5: ='Data Sheet'!B43 -> 0 | C5: ='Data Sheet'!C43 -> 0 | D5: ='Data Sheet'!D43 -> 0 | E5: ='Data Sheet'!E43 -> 0 | F5: ='Data Sheet'!F43 -> 0 | G5: ='Data Sheet'!G43 -> 0 | H5: ='Data Sheet'!H43 -> 0 | I5: ='Data Sheet'!I43 -> 0 | ... K5: ='Data Sheet'!K43 -> 0
A6: Operating Profit | B6: ='Data Sheet'!B50 -> 0 | C6: ='Data Sheet'!C50 -> 0 | D6: ='Data Sheet'!D50 -> 0 | E6: ='Data Sheet'!E50 -> 0 | F6: ='Data Sheet'!F50 -> 0 | G6: ='Data Sheet'!G50 -> 0 | H6: ='Data Sheet'!H50 -> 0 | I6: ='Data Sheet'!I50 -> 0 | ... K6: ='Data Sheet'!K50 -> 0
A7: Other Income | B7: ='Data Sheet'!B44 -> 0 | C7: ='Data Sheet'!C44 -> 0 | D7: ='Data Sheet'!D44 -> 0 | E7: ='Data Sheet'!E44 -> 0 | F7: ='Data Sheet'!F44 -> 0 | G7: ='Data Sheet'!G44 -> 0 | H7: ='Data Sheet'!H44 -> 0 | I7: ='Data Sheet'!I44 -> 0 | ... K7: ='Data Sheet'!K44 -> 0
A8: Depreciation | B8: ='Data Sheet'!B45 -> 0 | C8: ='Data Sheet'!C45 -> 0 | D8: ='Data Sheet'!D45 -> 0 | E8: ='Data Sheet'!E45 -> 0 | F8: ='Data Sheet'!F45 -> 0 | G8: ='Data Sheet'!G45 -> 0 | H8: ='Data Sheet'!H45 -> 0 | I8: ='Data Sheet'!I45 -> 0 | ... K8: ='Data Sheet'!K45 -> 0
A9: Interest | B9: ='Data Sheet'!B46 -> 0 | C9: ='Data Sheet'!C46 -> 0 | D9: ='Data Sheet'!D46 -> 0 | E9: ='Data Sheet'!E46 -> 0 | F9: ='Data Sheet'!F46 -> 0 | G9: ='Data Sheet'!G46 -> 0 | H9: ='Data Sheet'!H46 -> 0 | I9: ='Data Sheet'!I46 -> 0 | ... K9: ='Data Sheet'!K46 -> 0
A10: Profit before tax | B10: ='Data Sheet'!B47 -> 0 | C10: ='Data Sheet'!C47 -> 0 | D10: ='Data Sheet'!D47 -> 0 | E10: ='Data Sheet'!E47 -> 0 | F10: ='Data Sheet'!F47 -> 0 | G10: ='Data Sheet'!G47 -> 0 | H10: ='Data Sheet'!H47 -> 0 | I10: ='Data Sheet'!I47 -> 0 | ... K10: ='Data Sheet'!K47 -> 0
A11: Tax | B11: ='Data Sheet'!B48 -> 0 | C11: ='Data Sheet'!C48 -> 0 | D11: ='Data Sheet'!D48 -> 0 | E11: ='Data Sheet'!E48 -> 0 | F11: ='Data Sheet'!F48 -> 0 | G11: ='Data Sheet'!G48 -> 0 | H11: ='Data Sheet'!H48 -> 0 | I11: ='Data Sheet'!I48 -> 0 | ... K11: ='Data Sheet'!K48 -> 0
A12: Net profit | B12: ='Data Sheet'!B49 -> 0 | C12: ='Data Sheet'!C49 -> 0 | D12: ='Data Sheet'!D49 -> 0 | E12: ='Data Sheet'!E49 -> 0 | F12: ='Data Sheet'!F49 -> 0 | G12: ='Data Sheet'!G49 -> 0 | H12: ='Data Sheet'!H49 -> 0 | I12: ='Data Sheet'!I49 -> 0 | ... K12: ='Data Sheet'!K49 -> 0
A14: OPM | B14: =IF(B4>0,B6/B4,"") | C14: =IF(C4>0,C6/C4,"") | D14: =IF(D4>0,D6/D4,"") | E14: =IF(E4>0,E6/E4,"") | F14: =IF(F4>0,F6/F4,"") | G14: =IF(G4>0,G6/G4,"") | H14: =IF(H4>0,H6/H4,"") | I14: =IF(I4>0,I6/I4,"") | ... K14: =IF(K4>0,K6/K4,"")

Sheet Balance Sheet
A1: ='Profit & Loss'!A1 -> AXIS BANK LTD | E1: =UPDATE | J1: SCREENER.IN
A3: Narration | B3: ='Data Sheet'!B56 -> 42825 | C3: ='Data Sheet'!C56 -> 43190 | D3: ='Data Sheet'!D56 -> 43555 | E3: ='Data Sheet'!E56 -> 43921 | F3: ='Data Sheet'!F56 -> 44286 | G3: ='Data Sheet'!G56 -> 44651 | H3: ='Data Sheet'!H56 -> 45016 | I3: ='Data Sheet'!I56 -> 45382 | ... K3: ='Data Sheet'!K56 -> 46112
A4: Equity Share Capital | B4: ='Data Sheet'!B57 -> 0 | C4: ='Data Sheet'!C57 -> 0 | D4: ='Data Sheet'!D57 -> 0 | G4: ='Data Sheet'!G57 -> 0 | H4: ='Data Sheet'!H57 -> 0 | I4: ='Data Sheet'!I57 -> 0
A5: Reserves | B5: ='Data Sheet'!B58 -> 0 | C5: ='Data Sheet'!C58 -> 0 | D5: ='Data Sheet'!D58 -> 0 | G5: ='Data Sheet'!G58 -> 0 | H5: ='Data Sheet'!H58 -> 0 | I5: ='Data Sheet'!I58 -> 0
A6: Borrowings | B6: ='Data Sheet'!B59 -> 0 | C6: ='Data Sheet'!C59 -> 0 | D6: ='Data Sheet'!D59 -> 0 | G6: ='Data Sheet'!G59 -> 0 | H6: ='Data Sheet'!H59 -> 0 | I6: ='Data Sheet'!I59 -> 0
A7: Other Liabilities | B7: ='Data Sheet'!B60 -> 0 | C7: ='Data Sheet'!C60 -> 0 | D7: ='Data Sheet'!D60 -> 0 | G7: ='Data Sheet'!G60 -> 0 | H7: ='Data Sheet'!H60 -> 0 | I7: ='Data Sheet'!I60 -> 0
A8: Total | B8: ='Data Sheet'!B61 -> 0 | C8: ='Data Sheet'!C61 -> 0 | D8: ='Data Sheet'!D61 -> 0 | G8: ='Data Sheet'!G61 -> 0 | H8: ='Data Sheet'!H61 -> 0 | I8: ='Data Sheet'!I61 -> 0
A10: Net Block | B10: ='Data Sheet'!B62 -> 0 | C10: ='Data Sheet'!C62 -> 0 | D10: ='Data Sheet'!D62 -> 0 | G10: ='Data Sheet'!G62 -> 0 | H10: ='Data Sheet'!H62 -> 0 | I10: ='Data Sheet'!I62 -> 0
A11: Capital Work in Progress | B11: ='Data Sheet'!B63 -> 0 | C11: ='Data Sheet'!C63 -> 0 | D11: ='Data Sheet'!D63 -> 0 | G11: ='Data Sheet'!G63 -> 0 | H11: ='Data Sheet'!H63 -> 0 | I11: ='Data Sheet'!I63 -> 0
A12: Investments | B12: ='Data Sheet'!B64 -> 0 | C12: ='Data Sheet'!C64 -> 0 | D12: ='Data Sheet'!D64 -> 0 | G12: ='Data Sheet'!G64 -> 0 | H12: ='Data Sheet'!H64 -> 0 | I12: ='Data Sheet'!I64 -> 0
A13: Other Assets | B13: ='Data Sheet'!B65 -> 0 | C13: ='Data Sheet'!C65 -> 0 | D13: ='Data Sheet'!D65 -> 0 | G13: ='Data Sheet'!G65 -> 0 | H13: ='Data Sheet'!H65 -> 0 | I13: ='Data Sheet'!I65 -> 0
A14: Total | B14: ='Data Sheet'!B66 -> 0 | C14: ='Data Sheet'!C66 -> 0 | D14: ='Data Sheet'!D66 -> 0 | G14: ='Data Sheet'!G66 -> 0 | H14: ='Data Sheet'!H66 -> 0 | I14: ='Data Sheet'!I66 -> 0
A16: Working Capital | B16: =B13-B7 -> 0 | C16: =C13-C7 -> 0 | D16: =D13-D7 -> 0 | G16: =G13-G7 -> 0 | H16: =H13-H7 -> 0 | I16: =I13-I7 -> 0
A17: Debtors | B17: ='Data Sheet'!B67 -> 0 | C17: ='Data Sheet'!C67 -> 0 | D17: ='Data Sheet'!D67 -> 0 | G17: ='Data Sheet'!G67 -> 0 | H17: ='Data Sheet'!H67 -> 0 | I17: ='Data Sheet'!I67 -> 0
A18: Inventory | B18: ='Data Sheet'!B68 -> 0 | C18: ='Data Sheet'!C68 -> 0 | D18: ='Data Sheet'!D68 -> 0 | G18: ='Data Sheet'!G68 -> 0 | H18: ='Data Sheet'!H68 -> 0 | I18: ='Data Sheet'!I68 -> 0
A20: Debtor Days | B20: =IF('Profit & Loss'!B4>0,'Balance Sheet'!B17/('Profit & Loss'!B4/365),0) -> 0 | C20: =IF('Profit & Loss'!C4>0,'Balance Sheet'!C17/('Profit & Loss'!C4/365),0) -> 0 | D20: =IF('Profit & Loss'!D4>0,'Balance Sheet'!D17/('Profit & Loss'!D4/365),0) -> 0 | G20: =IF('Profit & Loss'!G4>0,'Balance Sheet'!G17/('Profit & Loss'!G4/365),0) -> 0 | H20: =IF('Profit & Loss'!H4>0,'Balance Sheet'!H17/('Profit & Loss'!H4/365),0) -> 0 | I20: =IF('Profit & Loss'!I4>0,'Balance Sheet'!I17/('Profit & Loss'!I4/365),0) -> 0
A21: Inventory Turnover | B21: =IF('Balance Sheet'!B18>0,'Profit & Loss'!B4/'Balance Sheet'!B18,0) -> 0 | C21: =IF('Balance Sheet'!C18>0,'Profit & Loss'!C4/'Balance Sheet'!C18,0) -> 0 | D21: =IF('Balance Sheet'!D18>0,'Profit & Loss'!D4/'Balance Sheet'!D18,0) -> 0 | G21: =IF('Balance Sheet'!G18>0,'Profit & Loss'!G4/'Balance Sheet'!G18,0) -> 0 | H21: =IF('Balance Sheet'!H18>0,'Profit & Loss'!H4/'Balance Sheet'!H18,0) -> 0 | I21: =IF('Balance Sheet'!I18>0,'Profit & Loss'!I4/'Balance Sheet'!I18,0) -> 0
A23: Return on Equity | B23: =IF(SUM('Balance Sheet'!B4:B5)>0,'Profit & Loss'!B12/SUM('Balance Sheet'!B4:B5),"") | C23: =IF(SUM('Balance Sheet'!C4:C5)>0,'Profit & Loss'!C12/SUM('Balance Sheet'!C4:C5),"") | D23: =IF(SUM('Balance Sheet'!D4:D5)>0,'Profit & Loss'!D12/SUM('Balance Sheet'!D4:D5),"") | F23: =IF(SUM('Balance Sheet'!F4:F5)>0,'Profit & Loss'!F12/SUM('Balance Sheet'!F4:F5),"") | G23: =IF(SUM('Balance Sheet'!G4:G5)>0,'Profit & Loss'!G12/SUM('Balance Sheet'!G4:G5),"") | H23: =IF(SUM('Balance Sheet'!H4:H5)>0,'Profit & Loss'!H12/SUM('Balance Sheet'!H4:H5),"") | I23: =IF(SUM('Balance Sheet'!I4:I5)>0,'Profit & Loss'!I12/SUM('Balance Sheet'!I4:I5),"") | J23: =IF(SUM('Balance Sheet'!J4:J5)>0,'Profit & Loss'!J12/SUM('Balance Sheet'!J4:J5),"") | K23: =IF(SUM('Balance Sheet'!K4:K5)>0,'Profit & Loss'!K12/SUM('Balance Sheet'!K4:K5),"")
A24: Return on Capital Emp | C24: =IF((B4+B5+B6+C4+C5+C6)>0,('Profit & Loss'!C10+'Profit & Loss'!C9)*2/(B4+B5+B6+C4+C5+C6),"") | D24: =IF((C4+C5+C6+D4+D5+D6)>0,('Profit & Loss'!D10+'Profit & Loss'!D9)*2/(C4+C5+C6+D4+D5+D6),"") | E24: =IF((D4+D5+D6+E4+E5+E6)>0,('Profit & Loss'!E10+'Profit & Loss'!E9)*2/(D4+D5+D6+E4+E5+E6),"") | F24: =IF((E4+E5+E6+F4+F5+F6)>0,('Profit & Loss'!F10+'Profit & Loss'!F9)*2/(E4+E5+E6+F4+F5+F6),"") | G24: =IF((F4+F5+F6+G4+G5+G6)>0,('Profit & Loss'!G10+'Profit & Loss'!G9)*2/(F4+F5+F6+G4+G5+G6),"") | H24: =IF((G4+G5+G6+H4+H5+H6)>0,('Profit & Loss'!H10+'Profit & Loss'!H9)*2/(G4+G5+G6+H4+H5+H6),"") | I24: =IF((H4+H5+H6+I4+I5+I6)>0,('Profit & Loss'!I10+'Profit & Loss'!I9)*2/(H4+H5+H6+I4+I5+I6),"") | J24: =IF((I4+I5+I6+J4+J5+J6)>0,('Profit & Loss'!J10+'Profit & Loss'!J9)*2/(I4+I5+I6+J4+J5+J6),"") | K24: =IF((J4+J5+J6+K4+K5+K6)>0,('Profit & Loss'!K10+'Profit & Loss'!K9)*2/(J4+J5+J6+K4+K5+K6),"")

Sheet Cash Flow
A1: ='Balance Sheet'!A1 -> AXIS BANK LTD | E1: =UPDATE | J1: SCREENER.IN
A3: Narration | B3: ='Data Sheet'!B81 -> 42825 | C3: ='Data Sheet'!C81 -> 43190 | D3: ='Data Sheet'!D81 -> 43555 | E3: ='Data Sheet'!E81 -> 43921 | F3: ='Data Sheet'!F81 -> 44286 | G3: ='Data Sheet'!G81 -> 44651 | H3: ='Data Sheet'!H81 -> 45016 | I3: ='Data Sheet'!I81 -> 45382 | ... K3: ='Data Sheet'!K81 -> 46112
A4: Cash from Operating Activity | B4: ='Data Sheet'!B82 -> 32208.62 | C4: ='Data Sheet'!C82 -> -38390.3 | D4: ='Data Sheet'!D82 -> 37125.25
A5: Cash from Investing Activity | B5: ='Data Sheet'!B83 -> -12458.4 | C5: ='Data Sheet'!C83 -> -10007.1 | D5: ='Data Sheet'!D83 -> -18674.35
A6: Cash from Financing Activity | B6: ='Data Sheet'!B84 -> -2486.91 | C6: ='Data Sheet'!C84 -> 41342.09 | D6: ='Data Sheet'!D84 -> 5642.6
A7: Net Cash Flow | B7: ='Data Sheet'!B85 -> 17263.31 | C7: ='Data Sheet'!C85 -> -7055.3 | D7: ='Data Sheet'!D85 -> 24093.5

Sheet Data Sheet
A1: COMPANY NAME | B1: AXIS BANK LTD | E1: =IF(B2<>B3, "A NEW VERSION OF THE WORKSHEET IS AVAILABLE", "")
A2: LATEST VERSION | B2: 2.1 | E2: PLEASE DO NOT MAKE ANY CHANGES TO THIS SHEET
A3: CURRENT VERSION | B3: 2.1
A5: META
A6: Number of shares | B6: =IF(B9>0, B9/B8, 0) -> 311.13633
A7: Face Value | B7: 2
A8: Current Price | B8: 1251.65
A9: Market Capitalization | B9: 389433.79
A15: PROFIT & LOSS
A16: Report Date | B16: 42825 | C16: 43190 | D16: 43555 | E16: 43921 | F16: 44286 | G16: 44651 | H16: 45016 | I16: 45382 | J16: 45747 | K16: 46112
A17: Sales
A18: Raw Material Cost
A19: Change in Inventory
A20: Power and Fuel
A21: Other Mfr. Exp
A22: Employee Cost
A23: Selling and admin
A24: Other Expenses
A25: Other Income
A26: Depreciation
A27: Interest
A28: Profit before tax
... A40: Quarters
A41: Report Date | B41: 45382 | C41: 45473 | D41: 45565 | E41: 45657 | F41: 45747 | G41: 45838 | H41: 45930 | I41: 46022 | J41: 46112 | K41: 46203
A42: Sales
A43: Expenses
A44: Other Income
A45: Depreciation
A46: Interest
A47: Profit before tax
A48: Tax
A49: Net profit
A50: Operating Profit
A55: BALANCE SHEET
A56: Report Date | B56: 42825 | C56: 43190 | D56: 43555 | E56: 43921 | F56: 44286 | G56: 44651 | H56: 45016 | I56: 45382 | J56: 45747 | K56: 46112
A57: Equity Share Capital
A58: Reserves
A59: Borrowings
A60: Other Liabilities
A61: Total
...
